Різниця стає очевидною, якщо ми подивимося на код всередині функції.

Поведінка відрізняється, якщо код може раптово вийти з `try...catch`.

Наприклад, якщо є `return` всередині `try...catch`. Блок `finally` спрацює для "будь-якого" виходу з `try...catch`, навіть за допомогою `return`. Одразу після виходу `try...catch`, але перед передачею контролю коду, що викликав.

```js run
function f() {
  try {
    alert('початок');
*!*
    return "результат";
*/!*
  } catch (err) {
    /// ...
  } finally {
    alert('очищення!');
  }
}

f(); // очищення!
```

...Or when there's a `throw`, like here:
...Або якщо є `throw`:

```js run
function f() {
  try {
    alert('початок');
    throw new Error("помилка");
  } catch (err) {
    // ...
    if("не можу обробити помилку") {
*!*
      throw err;
*/!*
    }

  } finally {
    alert('очищення!')
  }
}

f(); // очищення!
```

`finally` гарантує очищення. Очищення не спрацює, якщо ми просто додамо код в кінці функції `f`.
